Workbook

Sheet Executive Summary
A1: BEST BUY MARKETPLACE PRODUCT DATA QUALITY REPORT
A2: Executive Summary | Reporting Period: Q2 FY2026 | Prepared: June 01, 2026 | Analyst: Akash Singh, M.S. Business Analytics
A4: BUSINESS CONTEXT
A5: Best Buy launched its U.S. digital Marketplace in mid-FY2026, dramatically expanding product count through third-party sellers (Best Buy Q4 FY2026 Earnings Call, Mar 2026). This expansion introduced significant data quality risk: inconsistent seller attributes, GTIN validation failures, and stale listings threaten search discoverability, AI-recommendation accuracy, and regulatory compliance. This audit covers 1,040 marketplace product records across 8 active sellers and 5 product categories.
A7: KEY FINDINGS
A8: 1,040 | B8: Total product records audited across all marketplace sellers
A9: 829 (79.7%) | B9: Records fully compliant with Best Buy PDM requirements
A10: 211 (20.3%) | B10: Records with at least one data quality violation
A11: 42 | B11: Critical violations (missing required fields auto-suppressed by BB algorithm)
A12: 40 | B12: Duplicate SKUs detected billing and commission risk per Marketplace Program Policy
A13: 19 | B13: GTIN/UPC mismatches inventory recognition failures at RDC
A15: RECOMMENDATIONS
A16: IMMEDIATE (0-30 days) | B16: Suppress 42 critical listings with missing required fields. Notify affected sellers with remediation SLA of 7 business days.
A17: SHORT-TERM (30-90 days) | B17: Implement automated GTIN validation at listing ingestion. Deploy LAMBDA-based audit rules as live data validation layer in PDM portal.
A18: MEDIUM-TERM (90-180 days) | B18: Establish Seller Data Quality Score (CALC_DQ_SCORE 85%) as prerequisite for Marketplace promotional eligibility. Monthly scorecard review.
A19: GOVERNANCE | B19: Align audit rules with Best Buy Marketplace Standard Terms (Apr 2025, 3 Required Product Information). Reference GS1 GTIN standard for UPC validation.

Sheet Raw Catalog
A1: Row_ID | B1: SKU | C1: Seller_ID | D1: Seller_Name | E1: Category | F1: Brand | G1: Model_Name | H1: Model_Number | I1: UPC | J1: GTIN | K1: Title | L1: Description | M1: Price_USD | N1: Weight_lbs | O1: Stock_Quantity | P1: Primary_Image_URL | Q1: Specifications | R1: Listing_Date | S1: Last_Updated | T1: Is_Active | U1: Data_Quality_Issue
A2: 1 | B2: BB-MKT-00357 | C2: S008 | D2: DigitalHub USA | E2: Tablets | F2: Apple | G2: Galaxy Tab S9 | H2: AP-3591-BL | I2: 823004112457 | J2: 0823004112457 | K2: Apple Galaxy Tab S9 12.9" 128GB Tablet | L2: Stay productive and entertained with the Apple Galaxy Tab S9. Powerful performance in a sleek design. | M2: 1222.55 | N2: 0.84 | O2: 281 | P2: https://images.bestbuy.com/marketplace/apple-galaxy-tab-s9-main.jpg | Q2: Storage_GB: 128 | Screen_Size: 12.9" | Cellular: No | RAM_GB: 16 | R2: 2024-12-14 | S2: 2024-12-14 | T2: Yes
A3: 2 | B3: BB-MKT-00833 | C3: S006 | D3: NextGen Devices | E3: Smart Home | F3: Wyze | G3: Learning Thermostat | H3: WY-9007-BL | I3: 929827299135 | J3: 0929827299135 | K3: Wyze Learning Thermostat Smart Home Device | L3: Transform your home with the Wyze Learning Thermostat. Easy setup and seamless smart home integration. | M3: 176.12 | N3: 1.01 | O3: 164 | P3: https://images.bestbuy.com/marketplace/wyze-learning-thermostat-main.jpg | Q3: Connectivity: Wi-Fi | Voice_Assistant: Apple HomeKit | Power: USB-C | R3: 2025-02-22 | S3: 2025-02-22 | T3: Yes
A4: 3 | B4: BB-MKT-00543 | C4: S007 | D4: SmartBuy Co | E4: Laptops | G4: Katana 15 | H4: AS-9516-SL | I4: 979237227132 | J4: 0979237227132 | K4: ASUS Katana 15 14" Laptop - 8GB RAM 1024GB SSD | L4: Experience premium performance with the ASUS Katana 15. Designed for professionals and students alike. | M4: 1279.54 | N4: 2.62 | O4: 358 | P4: https://images.bestbuy.com/marketplace/asus-katana-15-main.jpg | Q4: RAM_GB: 8 | Storage_GB: 1024 | Screen_Size: 14" | Processor: Apple M2 | R4: 2025-04-10 | S4: 2025-04-10 | T4: Yes | U4: MISSING_BRAND
A5: 4 | B5: BB-MKT-00087 | C5: S006 | D5: NextGen Devices | E5: TVs | F5: Hisense | G5: QLED 4K | H5: HI-6793-BL | I5: 551496545441 | J5: 0551496545441 | K5: Hisense 75" 1080p Full HD Smart TV QLED 4K | L5: Immerse yourself in stunning visuals with the Hisense QLED 4K. Features cutting-edge display technology. | M5: 3504.35 | N5: 39.73 | O5: 495 | P5: https://images.bestbuy.com/marketplace/hisense-qled-4k-main.jpg | Q5: Screen_Size: 75" | Resolution: 1080p Full HD | Smart_TV: No | HDR: HDR10+ | R5: 2024-11-25 | S5: 2024-11-25 | T5: Yes
A6: 5 | B6: BB-MKT-00309 | C6: S007 | D6: SmartBuy Co | E6: Smart Home | F6: Wyze | G6: Ultra 2 | H6: WY-8723-BL | I6: 590556533399 | J6: 0590556533399 | K6: Wyze Ultra 2 Smart Home Device | L6: Transform your home with the Wyze Ultra 2. Easy setup and seamless smart home integration. | M6: 109.17 | N6: 1.26 | O6: 307 | P6: https://images.bestbuy.com/marketplace/wyze-ultra-2-main.jpg | Q6: Connectivity: Wi-Fi | Voice_Assistant: Apple HomeKit | Power: Battery | R6: 2024-09-12 | S6: 2024-09-12 | T6: Yes
A7: 6 | B7: BB-MKT-00030 | C7: S002 | D7: EliteGadgets Inc | E7: Tablets | F7: Amazon | G7: Galaxy Tab S9 | H7: AM-4228-SL | I7: 691874457344 | J7: 0691874457344 | K7: Amazon Galaxy Tab S9 8" 256GB Tablet | L7: Stay productive and entertained with the Amazon Galaxy Tab S9. Powerful performance in a sleek design. | M7: 644.99 | N7: 0.87 | O7: 471 | P7: https://images.bestbuy.com/marketplace/amazon-galaxy-tab-s9-main.jpg | Q7: Storage_GB: 256 | Screen_Size: 8" | Cellular: No | RAM_GB: 4 | R7: 2024-12-17 | S7: 2024-12-17 | T7: Yes
A8: 7 | B8: BB-MKT-00798 | C8: S001 | D8: TechDirect LLC | E8: Laptops | F8: Lenovo | G8: Aspire 5 | H8: LE-8207-BK | I8: 119167254787 | J8: 0119167254787 | K8: Lenovo Aspire 5 14" Laptop - 32GB RAM 512GB SSD | L8: Experience premium performance with the Lenovo Aspire 5. Designed for professionals and students alike. | M8: 1378.52 | N8: 2.75 | O8: 245 | P8: https://images.bestbuy.com/marketplace/lenovo-aspire-5-main.jpg | Q8: RAM_GB: 32 | Storage_GB: 512 | Screen_Size: 14" | Processor: AMD Ryzen 7 | R8: 2025-04-11 | S8: 2025-04-11 | T8: Yes
A9: 8 | B9: BB-MKT-00019 | C9: S002 | D9: EliteGadgets Inc | E9: TVs | F9: Samsung | G9: U8K | H9: SA-5033-BK | I9: 726594012825 | J9: 0726594012825 | K9: Samsung 43" 1080p Full HD Smart TV U8K | L9: Immerse yourself in stunning visuals with the Samsung U8K. Features cutting-edge display technology. | M9: 2571.68 | N9: 26.45 | O9: 298 | P9: https://images.bestbuy.com/marketplace/samsung-u8k-main.jpg | Q9: Screen_Size: 43" | Resolution: 1080p Full HD | Smart_TV: Yes | HDR: Dolby Vision | R9: 2025-04-16 | S9: 2025-04-16 | T9: Yes
A10: 9 | B10: BB-MKT-00326 | C10: S001 | D10: TechDirect LLC | E10: Smart Home | F10: Amazon | G10: Hue Starter Kit | H10: AM-5501-BL | I10: 642520584597 | J10: 0642520584597 | K10: Amazon Hue Starter Kit Smart Home Device | L10: Transform your home with the Amazon Hue Starter Kit. Easy setup and seamless smart home integration. | M10: 114.95 | N10: 1.17 | O10: 261 | P10: https://images.bestbuy.com/marketplace/amazon-hue-starter-kit-main.jpg | Q10: Connectivity: Bluetooth | Voice_Assistant: Apple HomeKit | Power: USB-C | R10: 2024-11-21 | S10: 2024-11-21 | T10: Yes
A11: 10 | B11: BB-MKT-00903 | C11: S003 | D11: PrimeElectronics | E11: Headphones | F11: Bose | G11: QuietComfort 45 | H11: BO-6335-BL | I11: 274644497411 | J11: 0274644497411 | K11: Bose QuietComfort 45 On-ear Wireless Headphones | L11: Enjoy crystal-clear audio with the Bose QuietComfort 45. Perfect for music lovers and remote workers. | M11: 368.82 | N11: 0.4 | O11: 399 | P11: https://images.bestbuy.com/marketplace/bose-quietcomfort-45-main.jpg | Q11: Type: On-ear | Connectivity: Wireless | ANC: Yes | Battery_Hours: 40 | R11: 2024-11-15 | S11: 2024-11-15 | T11: Yes
A12: 11 | B12: BB-MKT-00900 | C12: S005 | D12: ConnectPro Sales | E12: Headphones | F12: Apple | G12: Studio Pro | H12: AP-9242-SL | I12: 717091634913 | J12: 0717091634913 | K12: Apple Studio Pro In-ear Wireless Headphones | L12: Enjoy crystal-clear audio with the Apple Studio Pro. Perfect for music lovers and remote workers. | M12: 354.48 | N12: 0.23 | O12: 387 | P12: https://images.bestbuy.com/marketplace/apple-studio-pro-main.jpg | Q12: Type: In-ear | Connectivity: Wireless | ANC: No | Battery_Hours: 30 | R12: 2024-10-02 | S12: 2024-10-02 | T12: Yes
A13: 12 | B13: BB-MKT-00826 | C13: S005 | D13: ConnectPro Sales | E13: TVs | F13: Sony | G13: Bravia XR | H13: SO-9627-BK | I13: 929014709335 | J13: 0929014709335 | K13: Sony 65" 4K UHD Smart TV Bravia XR | L13: Immerse yourself in stunning visuals with the Sony Bravia XR. Features cutting-edge display technology. | M13: 2129.62 | N13: 42.82 | O13: 21 | P13: https://images.bestbuy.com/marketplace/sony-bravia-xr-main.jpg | Q13: Screen_Size: 65" | Resolution: 4K UHD | Smart_TV: Yes | HDR: HDR10 | R13: 2024-09-19 | S13: 2024-09-19 | T13: Yes
A14: 13 | B14: BB-MKT-00633 | C14: S006 | D14: NextGen Devices | E14: Laptops | F14: Dell | G14: VivoBook 16 | H14: DE-9693-SL | I14: 235729166419 | J14: 0235729166419 | K14: Dell VivoBook 16 14" Laptop - 64GB RAM 1024GB SSD | L14: Experience premium performance with the Dell VivoBook 16. Designed for professionals and students alike. | M14: 2396.23 | N14: 2.4 | O14: 127 | P14: https://images.bestbuy.com/marketplace/dell-vivobook-16-main.jpg | Q14: RAM_GB: 64 | Storage_GB: 1024 | Screen_Size: 14" | Processor: Intel i5 | R14: 2025-01-05 | S14: 2025-01-05 | T14: Yes
A15: 14 | B15: BB-MKT-00757 | C15: S008 | D15: DigitalHub USA | E15: Headphones | F15: Apple | G15: Tour One | H15: AP-8935-BK | I15: 670764098449 | J15: 0670764098449 | K15: Apple Tour One Over-ear Wired Headphones | L15: Enjoy crystal-clear audio with the Apple Tour One. Perfect for music lovers and remote workers. | M15: 169.37 | N15: 0.33 | O15: 327 | P15: https://images.bestbuy.com/marketplace/apple-tour-one-main.jpg | Q15: Type: Over-ear | Connectivity: Wired | ANC: No | Battery_Hours: 30 | R15: 2024-07-11 | S15: 2024-07-11 | T15: Yes
A16: 15 | B16: BB-MKT-00086 | C16: S008 | D16: DigitalHub USA | E16: Tablets | F16: Lenovo | G16: iPad Pro 12.9 | H16: LE-8770-BK | I16: 852274855980 | J16: 0852274855980 | K16: Lenovo iPad Pro 12.9 12.4" 256GB Tablet | L16: Stay productive and entertained with the Lenovo iPad Pro 12.9. Powerful performance in a sleek design. | M16: 253.91 | N16: 0.35 | O16: 221 | P16: https://images.bestbuy.com/marketplace/lenovo-ipad-pro-12.9-main.jpg | Q16: Storage_GB: 256 | Screen_Size: 12.4" | Cellular: No | RAM_GB: 8 | R16: 2024-08-19 | S16: 2024-08-19 | T16: Yes
A17: 16 | B17: BB-MKT-00189 | C17: S003 | D17: PrimeElectronics | E17: Smart Home | F17: Nest | G17: Learning Thermostat | H17: NE-9804-WH | I17: 633373750765 | J17: 0633373750765 | K17: Nest Learning Thermostat Smart Home Device | L17: Transform your home with the Nest Learning Thermostat. Easy setup and seamless smart home integration. | M17: 289.81 | N17: 0.79 | O17: 71 | P17: https://images.bestbuy.com/marketplace/nest-learning-thermostat-main.jpg | Q17: Connectivity: Zigbee | Voice_Assistant: None | Power: Wired | R17: 2024-10-04 | S17: 2024-10-04 | T17: Yes
A18: 17 | B18: BB-MKT-00407 | C18: S003 | D18: PrimeElectronics | E18: Tablets | F18: Lenovo | G18: iPad Pro 12.9 | H18: LE-6606-WH | I18: 965724580023 | J18: 0466172926771 | K18: Lenovo iPad Pro 12.9 10.1" 256GB Tablet | L18: Stay productive and entertained with the Lenovo iPad Pro 12.9. Powerful performance in a sleek design. | M18: 348.05 | N18: 0.7 | O18: 378 | P18: https://images.bestbuy.com/marketplace/lenovo-ipad-pro-12.9-main.jpg | Q18: Storage_GB: 256 | Screen_Size: 10.1" | Cellular: No | RAM_GB: 12 | R18: 2025-04-20 | S18: 2025-04-20 | T18: Yes | U18: GTIN_UPC_MISMATCH
A19: 18 | B19: BB-MKT-00004 | C19: S002 | D19: EliteGadgets Inc | E19: Smart Home | F19: Ring | G19: Hue Starter Kit | H19: RI-4733-SL | I19: 147543377362 | J19: 0147543377362 | K19: Ring Hue Starter Kit Smart Home Device | L19: Transform your home with the Ring Hue Starter Kit. Easy setup and seamless smart home integration. | M19: 492.05 | N19: 1.3 | O19: 443 | P19: https://images.bestbuy.com/marketplace/ring-hue-starter-kit-main.jpg | Q19: Connectivity: Z-Wave | Voice_Assistant: Google Assistant | Power: USB-C | R19: 2024-08-21 | S19: 2024-08-21 | T19: Yes
A20: 19 | B20: BB-MKT-00729 | C20: S004 | D20: ValueTech Store | E20: Headphones | F20: Bose | G20: Momentum 4 | H20: BO-5505-BK | I20: 158666065098 | J20: 0158666065098 | K20: Bose Momentum 4 Over-ear Both Headphones | L20: Enjoy crystal-clear audio with the Bose Momentum 4. Perfect for music lovers and remote workers. | M20: 515.19 | N20: 0.36 | O20: 326 | P20: https://images.bestbuy.com/marketplace/bose-momentum-4-main.jpg | Q20: Type: Over-ear | Connectivity: Both | ANC: No | Battery_Hours: 30 | R20: 2025-04-23 | S20: 2025-04-23 | T20: Yes
A21: 20 | B21: BB-MKT-00319 | C21: S008 | D21: DigitalHub USA | E21: Tablets | F21: Apple | G21: Galaxy Tab S9 | H21: AP-4795-WH | J21: 0669128469380 | K21: Apple Galaxy Tab S9 10.1" 256GB Tablet | L21: Stay productive and entertained with the Apple Galaxy Tab S9. Powerful performance in a sleek design. | M21: 924.13 | N21: 0.52 | O21: 335 | P21: https://images.bestbuy.com/marketplace/apple-galaxy-tab-s9-main.jpg | Q21: Storage_GB: 256 | Screen_Size: 10.1" | Cellular: Yes | RAM_GB: 16 | R21: 2024-07-01 | S21: 2024-07-01 | T21: Yes | U21: MISSING_UPC
A22: 21 | B22: BB-MKT-00247 | C22: S002 | D22: EliteGadgets Inc | E22: Smart Home | F22: Nest | G22: Nest Hub Max | H22: NE-1541-BL | I22: 370830447947 | J22: 0370830447947 | K22: Nest Nest Hub Max Smart Home Device | L22: Transform your home with the Nest Nest Hub Max. Easy setup and seamless smart home integration. | M22: 48.28 | N22: 0.6 | O22: 101 | P22: https://images.bestbuy.com/marketplace/nest-nest-hub-max-main.jpg | Q22: Connectivity: Wi-Fi | Voice_Assistant: Google Assistant | Power: Battery | R22: 2024-11-18 | S22: 2024-11-18 | T22: Yes | U22: DUPLICATE_SKU
A23: 22 | B23: BB-MKT-00230 | C23: S002 | D23: EliteGadgets Inc | E23: Headphones | F23: Apple | G23: AirPods Max | H23: AP-3854-SL | I23: 450680559005 | J23: 0450680559005 | K23: Apple AirPods Max Over-ear Wireless Headphones | L23: Enjoy crystal-clear audio with the Apple AirPods Max. Perfect for music lovers and remote workers. | M23: 145.08 | N23: 0.35 | O23: 89 | P23: https://images.bestbuy.com/marketplace/apple-airpods-max-main.jpg | Q23: Type: Over-ear | Connectivity: Wireless | ANC: No | Battery_Hours: 36 | R23: 2025-01-10 | S23: 2025-01-10 | T23: Yes
A24: 23 | B24: BB-MKT-00185 | C24: S001 | D24: TechDirect LLC | E24: Headphones | F24: Jabra | G24: WH-1000XM5 | H24: JA-3623-SL | I24: 706339659651 | J24: 0706339659651 | K24: Jabra WH-1000XM5 In-ear Wireless Headphones | L24: Enjoy crystal-clear audio with the Jabra WH-1000XM5. Perfect for music lovers and remote workers. | M24: 320.12 | N24: 0.44 | O24: 118 | P24: https://images.bestbuy.com/marketplace/jabra-wh-1000xm5-main.jpg | Q24: Type: In-ear | Connectivity: Wireless | ANC: Yes | Battery_Hours: 40 | R24: 2025-01-24 | S24: 2025-01-24 | T24: Yes
A25: 24 | B25: BB-MKT-00359 | C25: S001 | D25: TechDirect LLC | E25: Headphones | F25: Sennheiser | G25: WH-1000XM5 | H25: SE-6159-BK | I25: 332881230114 | J25: 0332881230114 | K25: Sennheiser WH-1000XM5 In-ear Wireless Headphones | L25: Enjoy crystal-clear audio with the Sennheiser WH-1000XM5. Perfect for music lovers and remote workers. | M25: 430.19 | N25: 0.44 | O25: 421 | P25: https://images.bestbuy.com/marketplace/sennheiser-wh-1000xm5-main.jpg | Q25: Type: In-ear | Connectivity: Wireless | ANC: No | Battery_Hours: 20 | R25: 2024-11-19 | S25: 2024-11-19 | T25: Yes
A26: 25 | B26: BB-MKT-00513 | C26: S001 | D26: TechDirect LLC | E26: Headphones | F26: Sennheiser | G26: Momentum 4 | H26: SE-1673-WH | I26: 718012404580 | J26: 0718012404580 | K26: Sennheiser Momentum 4 On-ear Wired Headphones | L26: Enjoy crystal-clear audio with the Sennheiser Momentum 4. Perfect for music lovers and remote workers. | M26: 164.35 | N26: 0.33 | O26: 0 | P26: https://images.bestbuy.com/marketplace/sennheiser-momentum-4-main.jpg | Q26: Type: On-ear | Connectivity: Wired | ANC: No | Battery_Hours: 30 | R26: 2024-12-21 | S26: 2023-11-30 | T26: Yes | U26: STALE_LISTING
A27: 26 | B27: BB-MKT-00453 | C27: S004 | D27: ValueTech Store | E27: TVs | F27: Sony | G27: Bravia XR | H27: SO-7108-SL | I27: 168953380650 | J27: 0168953380650 | K27: Sony 55" 1080p Full HD Smart TV Bravia XR | L27: Immerse yourself in stunning visuals with the Sony Bravia XR. Features cutting-edge display technology. | M27: 1945.54 | N27: 30.06 | O27: 424 | P27: https://images.bestbuy.com/marketplace/sony-bravia-xr-main.jpg | Q27: Screen_Size: 55" | Resolution: 1080p Full HD | Smart_TV: No | HDR: Dolby Vision | R27: 2024-09-01 | S27: 2024-09-01 | T27: Yes
A28: 27 | B28: BB-MKT-00845 | C28: S007 | D28: SmartBuy Co | E28: Headphones | F28: Bose | G28: Evolve2 85 | H28: BO-1091-SL | I28: 312712561451 | J28: 0312712561451 | K28: Bose Evolve2 85 Over-ear Wireless Headphones | L28: Enjoy crystal-clear audio with the Bose Evolve2 85. Perfect for music lovers and remote workers. | M28: 3839.84 | N28: 0.43 | O28: 468 | P28: https://images.bestbuy.com/marketplace/bose-evolve2-85-main.jpg | Q28: Type: Over-ear | Connectivity: Wireless | ANC: No | Battery_Hours: 30 | R28: 2024-11-07 | S28: 2024-11-07 | T28: Yes | U28: PRICE_ANOMALY
A29: 28 | B29: BB-MKT-00932 | C29: S003 | D29: PrimeElectronics | E29: Headphones | F29: Apple | G29: Tour One | H29: AP-9370-WH | I29: 534576011084 | J29: 0534576011084 | K29: Apple Tour One On-ear Both Headphones | L29: Enjoy crystal-clear audio with the Apple Tour One. Perfect for music lovers and remote workers. | M29: 102.69 | N29: 0.37 | O29: 397 | P29: https://images.bestbuy.com/marketplace/apple-tour-one-main.jpg | Q29: Type: On-ear | Connectivity: Both | ANC: Yes | Battery_Hours: 40 | R29: 2024-07-09 | S29: 2024-07-09 | T29: Yes
A30: 29 | B30: BB-MKT-00799 | C30: S004 | D30: ValueTech Store | E30: Tablets | F30: Apple | G30: Fire HD 10 | H30: AP-5227-SL | I30: 299460168950 | J30: 0299460168950 | K30: Apple Fire HD 10 11" 64GB Tablet | L30: Stay productive and entertained with the Apple Fire HD 10. Powerful performance in a sleek design. | M30: 447.47 | N30: 0.6 | O30: 116 | P30: https://images.bestbuy.com/marketplace/apple-fire-hd-10-main.jpg | Q30: Storage_GB: 64 | Screen_Size: 11" | Cellular: No | RAM_GB: 4 | R30: 2024-09-28 | S30: 2024-09-28 | T30: Yes
A31: 30 | B31: BB-MKT-00448 | C31: S001 | D31: TechDirect LLC | E31: Tablets | F31: Amazon | G31: iPad Pro 12.9 | H31: AM-2605-BL | I31: 979651034336 | J31: 0979651034336 | K31: Amazon iPad Pro 12.9 12.9" 512GB Tablet | L31: Stay productive and entertained with the Amazon iPad Pro 12.9. Powerful performance in a sleek design. | M31: 718.58 | N31: 0.35 | O31: 385 | P31: https://images.bestbuy.com/marketplace/amazon-ipad-pro-12.9-main.jpg | Q31: Storage_GB: 512 | Screen_Size: 12.9" | Cellular: No | RAM_GB: 12 | R31: 2024-07-07 | S31: 2024-07-07 | T31: Yes
A32: 31 | B32: BB-MKT-00721 | C32: S007 | D32: SmartBuy Co | E32: Smart Home | F32: Philips | G32: Video Doorbell Pro 2 | H32: PH-3898-WH | I32: 509861786750 | J32: 0509861786750 | K32: Philips Video Doorbell Pro 2 Smart Home Device | L32: Transform your home with the Philips Video Doorbell Pro 2. Easy setup and seamless smart home integration. | M32: 284.1 | N32: 0.63 | O32: 432 | P32: https://images.bestbuy.com/marketplace/philips-video-doorbell-pro-2-main.jpg | Q32: Connectivity: Wi-Fi | Voice_Assistant: Google Assistant | Power: Wired | R32: 2025-02-09 | S32: 2025-02-09 | T32: Yes
A33: 32 | B33: BB-MKT-00306 | C33: S005 | D33: ConnectPro Sales | E33: Tablets | F33: Samsung | G33: Fire HD 10 | H33: SA-1108-WH | I33: 631685415257 | J33: 0631685415257 | K33: Samsung Fire HD 10 11" 512GB Tablet | L33: Stay productive and entertained with the Samsung Fire HD 10. Powerful performance in a sleek design. | M33: 654.88 | N33: 0.44 | O33: 263 | P33: https://images.bestbuy.com/marketplace/samsung-fire-hd-10-main.jpg | Q33: Storage_GB: 512 | Screen_Size: 11" | Cellular: No | RAM_GB: 12 | R33: 2024-11-21 | S33: 2024-11-21 | T33: Yes
A34: 33 | B34: BB-MKT-00700 | C34: S003 | D34: PrimeElectronics | E34: Smart Home | F34: Google | G34: Echo Show 10 | H34: GO-5227-SL | I34: 707541577390 | J34: 0707541577390 | K34: Google Echo Show 10 Smart Home Device | L34: Transform your home with the Google Echo Show 10. Easy setup and seamless smart home integration. | M34: 362.4 | N34: 0.69 | O34: 0 | P34: https://images.bestbuy.com/marketplace/google-echo-show-10-main.jpg | Q34: Connectivity: Bluetooth | Voice_Assistant: None | Power: USB-C | R34: 2024-11-17 | S34: 2023-12-06 | T34: Yes | U34: STALE_LISTING
A35: 34 | B35: BB-MKT-00246 | C35: S005 | D35: ConnectPro Sales | E35: Tablets | F35: Amazon | G35: iPad Pro 12.9 | H35: AM-9462-SL | I35: 635758278399 | J35: 0635758278399 | K35: Amazon iPad Pro 12.9 12.4" 128GB Tablet | L35: Stay productive and entertained with the Amazon iPad Pro 12.9. Powerful performance in a sleek design. | M35: 1093.17 | N35: 0.61 | O35: 0 | P35: https://images.bestbuy.com/marketplace/amazon-ipad-pro-12.9-main.jpg | Q35: Storage_GB: 128 | Screen_Size: 12.4" | Cellular: Yes | RAM_GB: 12 | R35: 2024-08-03 | S35: 2023-11-20 | T35: Yes | U35: STALE_LISTING
A36: 35 | B36: BB-MKT-00815 | C36: S004 | D36: ValueTech Store | E36: Headphones | F36: Bose | G36: WH-1000XM5 | H36: BO-9813-WH | I36: 696530775578 | J36: 0696530775578 | K36: Bose WH-1000XM5 Over-ear Both Headphones | L36: Enjoy crystal-clear audio with the Bose WH-1000XM5. Perfect for music lovers and remote workers. | M36: 32.47 | N36: 0.41 | O36: 13 | P36: https://images.bestbuy.com/marketplace/bose-wh-1000xm5-main.jpg | Q36: Type: Over-ear | Connectivity: Both | ANC: Yes | Battery_Hours: 20 | R36: 2025-01-06 | S36: 2025-01-06 | T36: Yes
A37: 36 | B37: BB-MKT-00969 | C37: S002 | D37: EliteGadgets Inc | E37: TVs | F37: TCL | G37: OLED C3 | H37: TC-4375-BK | I37: 520572158394 | J37: 0520572158394 | K37: TCL 75" 1080p Full HD Smart TV OLED C3 | L37: Immerse yourself in stunning visuals with the TCL OLED C3. Features cutting-edge display technology. | M37: 3715.17 | N37: 8.21 | O37: 123 | P37: https://images.bestbuy.com/marketplace/tcl-oled-c3-main.jpg | Q37: Screen_Size: 75" | Resolution: 1080p Full HD | Smart_TV: Yes | HDR: HDR10 | R37: 2024-12-17 | S37: 2024-12-17 | T37: Yes
A38: 37 | B38: BB-MKT-00780 | C38: S004 | D38: ValueTech Store | E38: Headphones | F38: JBL | G38: Tour One | H38: JB-8111-WH | I38: 279281185915 | J38: 0279281185915 | K38: JBL Tour One In-ear Wired Headphones | L38: Enjoy crystal-clear audio with the JBL Tour One. Perfect for music lovers and remote workers. | M38: 73.73 | N38: 0.21 | O38: 491 | P38: https://images.bestbuy.com/marketplace/jbl-tour-one-main.jpg | Q38: Type: In-ear | Connectivity: Wired | ANC: Yes | Battery_Hours: 24 | R38: 2024-08-19 | S38: 2024-08-19 | T38: Yes
A39: 38 | B39: BB-MKT-01000 | C39: S008 | D39: DigitalHub USA | E39: Smart Home | F39: Arlo | G39: Nest Hub Max | H39: AR-2003-BL | I39: 751444143907 | J39: 0751444143907 | K39: Arlo Nest Hub Max Smart Home Device | L39: Transform your home with the Arlo Nest Hub Max. Easy setup and seamless smart home integration. | M39: 115.92 | N39: 0.11 | O39: 90 | P39: https://images.bestbuy.com/marketplace/arlo-nest-hub-max-main.jpg | Q39: Connectivity: Bluetooth | Voice_Assistant: Apple HomeKit | Power: USB-C | R39: 2024-10-10 | S39: 2024-10-10 | T39: Yes
A40: 39 | B40: BB-MKT-00644 | C40: S006 | D40: NextGen Devices | E40: TVs | F40: Lenovo | G40: iPad Pro 12.9 | H40: LE-3144-SL | I40: 204770454921 | J40: 0204770454921 | K40: Lenovo iPad Pro 12.9 11" 256GB Tablet | L40: Stay productive and entertained with the Lenovo iPad Pro 12.9. Powerful performance in a sleek design. | M40: 1014.11 | N40: 0.65 | O40: 412 | P40: https://images.bestbuy.com/marketplace/lenovo-ipad-pro-12.9-main.jpg | Q40: Storage_GB: 256 | Screen_Size: 11" | Cellular: Yes | RAM_GB: 16 | R40: 2024-07-28 | S40: 2024-07-28 | T40: Yes | U40: CATEGORY_MISMATCH
...

Sheet Audit Engine
A1: BEST BUY MARKETPLACE PRODUCT DATA QUALITY AUDIT ENGINE
A2: Source: Marketplace Product Catalog (PDM Portal) | Best Buy 10-K FY2025 Ref: Marketplace Data Quality Initiative | Refreshed: June 01, 2026
A3: Row_ID | B3: SKU | C3: Seller_ID | D3: Seller_Name | E3: Category | F3: Brand | G3: UPC | H3: GTIN | I3: Title | J3: Price_USD | K3: Last_Updated | L3: Data_Quality_Issue | M3: UPC_Present | N3: GTIN_Match | O3: Title_OK | P3: Price_Range_OK | Q3: Image_Present | R3: Brand_Present | S3: Not_Stale | T3: Issue_Count | U3: Severity | V3: Action_Required
A4: 1 | B4: BB-MKT-00357 | C4: S008 | D4: DigitalHub USA | E4: Tablets | F4: Apple | G4: 823004112457 | H4: 0823004112457 | I4: Apple Galaxy Tab S9 12.9" 128GB Tablet | J4: 1222.55 | K4: 2024-12-14 | M4: =IF(G4<>"","PASS","FAIL - Missing UPC") -> PASS | N4: =IF(AND(G4<>"",H4<>""),IF("0"&G4=H4,"PASS","FAIL - GTIN Mismatch"),"SKIP") -> PASS | O4: =IF(I4="","FAIL - No Title",IF(LEN(I4)<=126,"PASS","FAIL - Title >"&126&" chars")) -> PASS | P4: =IF(J4>0,IF(J4<5000,"PASS","FLAG - Review Price"),"FAIL - Zero Price") -> PASS | Q4: =IF('Raw Catalog'!P2<>"","PASS","FAIL - No Image") -> PASS | R4: =IF(F4<>"","PASS","FAIL - No Brand") -> PASS | S4: =IF(K4="","FAIL - No Date",IF(TODAY()-DATEVALUE(K4)<=180,"PASS","FLAG - Stale >180d")) -> FLAG - Stale >180d | T4: =COUNTIF(M4:S4,"FAIL*")+COUNTIF(M4:S4,"FLAG*") -> 1 | U4: =IF(T4=0,"CLEAN",IF(T4=1,"MINOR",IF(T4<=3,"MODERATE","CRITICAL"))) -> MINOR | V4: =IF(U4="CLEAN","None",IF(U4="MINOR","Seller Notify",IF(U4="MODERATE","Listing Suspended","Immediate Removal"))) -> Seller Notify
A5: 2 | B5: BB-MKT-00833 | C5: S006 | D5: NextGen Devices | E5: Smart Home | F5: Wyze | G5: 929827299135 | H5: 0929827299135 | I5: Wyze Learning Thermostat Smart Home Device | J5: 176.12 | K5: 2025-02-22 | M5: =IF(G5<>"","PASS","FAIL - Missing UPC") -> PASS | N5: =IF(AND(G5<>"",H5<>""),IF("0"&G5=H5,"PASS","FAIL - GTIN Mismatch"),"SKIP") -> PASS | O5: =IF(I5="","FAIL - No Title",IF(LEN(I5)<=126,"PASS","FAIL - Title >"&126&" chars")) -> PASS | P5: =IF(J5>0,IF(J5<5000,"PASS","FLAG - Review Price"),"FAIL - Zero Price") -> PASS | Q5: =IF('Raw Catalog'!P3<>"","PASS","FAIL - No Image") -> PASS | R5: =IF(F5<>"","PASS","FAIL - No Brand") -> PASS | S5: =IF(K5="","FAIL - No Date",IF(TODAY()-DATEVALUE(K5)<=180,"PASS","FLAG - Stale >180d")) -> FLAG - Stale >180d | T5: =COUNTIF(M5:S5,"FAIL*")+COUNTIF(M5:S5,"FLAG*") -> 1 | U5: =IF(T5=0,"CLEAN",IF(T5=1,"MINOR",IF(T5<=3,"MODERATE","CRITICAL"))) -> MINOR | V5: =IF(U5="CLEAN","None",IF(U5="MINOR","Seller Notify",IF(U5="MODERATE","Listing Suspended","Immediate Removal"))) -> Seller Notify
A6: 3 | B6: BB-MKT-00543 | C6: S007 | D6: SmartBuy Co | E6: Laptops | G6: 979237227132 | H6: 0979237227132 | I6: ASUS Katana 15 14" Laptop - 8GB RAM 1024GB SSD | J6: 1279.54 | K6: 2025-04-10 | L6: MISSING_BRAND | M6: =IF(G6<>"","PASS","FAIL - Missing UPC") -> PASS | N6: =IF(AND(G6<>"",H6<>""),IF("0"&G6=H6,"PASS","FAIL - GTIN Mismatch"),"SKIP") -> PASS | O6: =IF(I6="","FAIL - No Title",IF(LEN(I6)<=126,"PASS","FAIL - Title >"&126&" chars")) -> PASS | P6: =IF(J6>0,IF(J6<5000,"PASS","FLAG - Review Price"),"FAIL - Zero Price") -> PASS | Q6: =IF('Raw Catalog'!P4<>"","PASS","FAIL - No Image") -> PASS | R6: =IF(F6<>"","PASS","FAIL - No Brand") -> FAIL - No Brand | S6: =IF(K6="","FAIL - No Date",IF(TODAY()-DATEVALUE(K6)<=180,"PASS","FLAG - Stale >180d")) -> FLAG - Stale >180d | T6: =COUNTIF(M6:S6,"FAIL*")+COUNTIF(M6:S6,"FLAG*") -> 2 | U6: =IF(T6=0,"CLEAN",IF(T6=1,"MINOR",IF(T6<=3,"MODERATE","CRITICAL"))) -> MODERATE | V6: =IF(U6="CLEAN","None",IF(U6="MINOR","Seller Notify",IF(U6="MODERATE","Listing Suspended","Immediate Removal"))) -> Listing Suspended
A7: 4 | B7: BB-MKT-00087 | C7: S006 | D7: NextGen Devices | E7: TVs | F7: Hisense | G7: 551496545441 | H7: 0551496545441 | I7: Hisense 75" 1080p Full HD Smart TV QLED 4K | J7: 3504.35 | K7: 2024-11-25 | M7: =IF(G7<>"","PASS","FAIL - Missing UPC") -> PASS | N7: =IF(AND(G7<>"",H7<>""),IF("0"&G7=H7,"PASS","FAIL - GTIN Mismatch"),"SKIP") -> PASS | O7: =IF(I7="","FAIL - No Title",IF(LEN(I7)<=126,"PASS","FAIL - Title >"&126&" chars")) -> PASS | P7: =IF(J7>0,IF(J7<5000,"PASS","FLAG - Review Price"),"FAIL - Zero Price") -> PASS | Q7: =IF('Raw Catalog'!P5<>"","PASS","FAIL - No Image") -> PASS | R7: =IF(F7<>"","PASS","FAIL - No Brand") -> PASS | S7: =IF(K7="","FAIL - No Date",IF(TODAY()-DATEVALUE(K7)<=180,"PASS","FLAG - Stale >180d")) -> FLAG - Stale >180d | T7: =COUNTIF(M7:S7,"FAIL*")+COUNTIF(M7:S7,"FLAG*") -> 1 | U7: =IF(T7=0,"CLEAN",IF(T7=1,"MINOR",IF(T7<=3,"MODERATE","CRITICAL"))) -> MINOR | V7: =IF(U7="CLEAN","None",IF(U7="MINOR","Seller Notify",IF(U7="MODERATE","Listing Suspended","Immediate Removal"))) -> Seller Notify
A8: 5 | B8: BB-MKT-00309 | C8: S007 | D8: SmartBuy Co | E8: Smart Home | F8: Wyze | G8: 590556533399 | H8: 0590556533399 | I8: Wyze Ultra 2 Smart Home Device | J8: 109.17 | K8: 2024-09-12 | M8: =IF(G8<>"","PASS","FAIL - Missing UPC") -> PASS | N8: =IF(AND(G8<>"",H8<>""),IF("0"&G8=H8,"PASS","FAIL - GTIN Mismatch"),"SKIP") -> PASS | O8: =IF(I8="","FAIL - No Title",IF(LEN(I8)<=126,"PASS","FAIL - Title >"&126&" chars")) -> PASS | P8: =IF(J8>0,IF(J8<5000,"PASS","FLAG - Review Price"),"FAIL - Zero Price") -> PASS | Q8: =IF('Raw Catalog'!P6<>"","PASS","FAIL - No Image") -> PASS | R8: =IF(F8<>"","PASS","FAIL - No Brand") -> PASS | S8: =IF(K8="","FAIL - No Date",IF(TODAY()-DATEVALUE(K8)<=180,"PASS","FLAG - Stale >180d")) -> FLAG - Stale >180d | T8: =COUNTIF(M8:S8,"FAIL*")+COUNTIF(M8:S8,"FLAG*") -> 1 | U8: =IF(T8=0,"CLEAN",IF(T8=1,"MINOR",IF(T8<=3,"MODERATE","CRITICAL"))) -> MINOR | V8: =IF(U8="CLEAN","None",IF(U8="MINOR","Seller Notify",IF(U8="MODERATE","Listing Suspended","Immediate Removal"))) -> Seller Notify
A9: 6 | B9: BB-MKT-00030 | C9: S002 | D9: EliteGadgets Inc | E9: Tablets | F9: Amazon | G9: 691874457344 | H9: 0691874457344 | I9: Amazon Galaxy Tab S9 8" 256GB Tablet | J9: 644.99 | K9: 2024-12-17 | M9: =IF(G9<>"","PASS","FAIL - Missing UPC") -> PASS | N9: =IF(AND(G9<>"",H9<>""),IF("0"&G9=H9,"PASS","FAIL - GTIN Mismatch"),"SKIP") -> PASS | O9: =IF(I9="","FAIL - No Title",IF(LEN(I9)<=126,"PASS","FAIL - Title >"&126&" chars")) -> PASS | P9: =IF(J9>0,IF(J9<5000,"PASS","FLAG - Review Price"),"FAIL - Zero Price") -> PASS | Q9: =IF('Raw Catalog'!P7<>"","PASS","FAIL - No Image") -> PASS | R9: =IF(F9<>"","PASS","FAIL - No Brand") -> PASS | S9: =IF(K9="","FAIL - No Date",IF(TODAY()-DATEVALUE(K9)<=180,"PASS","FLAG - Stale >180d")) -> FLAG - Stale >180d | T9: =COUNTIF(M9:S9,"FAIL*")+COUNTIF(M9:S9,"FLAG*") -> 1 | U9: =IF(T9=0,"CLEAN",IF(T9=1,"MINOR",IF(T9<=3,"MODERATE","CRITICAL"))) -> MINOR | V9: =IF(U9="CLEAN","None",IF(U9="MINOR","Seller Notify",IF(U9="MODERATE","Listing Suspended","Immediate Removal"))) -> Seller Notify
A10: 7 | B10: BB-MKT-00798 | C10: S001 | D10: TechDirect LLC | E10: Laptops | F10: Lenovo | G10: 119167254787 | H10: 0119167254787 | I10: Lenovo Aspire 5 14" Laptop - 32GB RAM 512GB SSD | J10: 1378.52 | K10: 2025-04-11 | M10: =IF(G10<>"","PASS","FAIL - Missing UPC") -> PASS | N10: =IF(AND(G10<>"",H10<>""),IF("0"&G10=H10,"PASS","FAIL - GTIN Mismatch"),"SKIP") -> PASS | O10: =IF(I10="","FAIL - No Title",IF(LEN(I10)<=126,"PASS","FAIL - Title >"&126&" chars")) -> PASS | P10: =IF(J10>0,IF(J10<5000,"PASS","FLAG - Review Price"),"FAIL - Zero Price") -> PASS | Q10: =IF('Raw Catalog'!P8<>"","PASS","FAIL - No Image") -> PASS | R10: =IF(F10<>"","PASS","FAIL - No Brand") -> PASS | S10: =IF(K10="","FAIL - No Date",IF(TODAY()-DATEVALUE(K10)<=180,"PASS","FLAG - Stale >180d")) -> FLAG - Stale >180d | T10: =COUNTIF(M10:S10,"FAIL*")+COUNTIF(M10:S10,"FLAG*") -> 1 | U10: =IF(T10=0,"CLEAN",IF(T10=1,"MINOR",IF(T10<=3,"MODERATE","CRITICAL"))) -> MINOR | V10: =IF(U10="CLEAN","None",IF(U10="MINOR","Seller Notify",IF(U10="MODERATE","Listing Suspended","Immediate Removal"))) -> Seller Notify
A11: 8 | B11: BB-MKT-00019 | C11: S002 | D11: EliteGadgets Inc | E11: TVs | F11: Samsung | G11: 726594012825 | H11: 0726594012825 | I11: Samsung 43" 1080p Full HD Smart TV U8K | J11: 2571.68 | K11: 2025-04-16 | M11: =IF(G11<>"","PASS","FAIL - Missing UPC") -> PASS | N11: =IF(AND(G11<>"",H11<>""),IF("0"&G11=H11,"PASS","FAIL - GTIN Mismatch"),"SKIP") -> PASS | O11: =IF(I11="","FAIL - No Title",IF(LEN(I11)<=126,"PASS","FAIL - Title >"&126&" chars")) -> PASS | P11: =IF(J11>0,IF(J11<5000,"PASS","FLAG - Review Price"),"FAIL - Zero Price") -> PASS | Q11: =IF('Raw Catalog'!P9<>"","PASS","FAIL - No Image") -> PASS | R11: =IF(F11<>"","PASS","FAIL - No Brand") -> PASS | S11: =IF(K11="","FAIL - No Date",IF(TODAY()-DATEVALUE(K11)<=180,"PASS","FLAG - Stale >180d")) -> FLAG - Stale >180d | T11: =COUNTIF(M11:S11,"FAIL*")+COUNTIF(M11:S11,"FLAG*") -> 1 | U11: =IF(T11=0,"CLEAN",IF(T11=1,"MINOR",IF(T11<=3,"MODERATE","CRITICAL"))) -> MINOR | V11: =IF(U11="CLEAN","None",IF(U11="MINOR","Seller Notify",IF(U11="MODERATE","Listing Suspended","Immediate Removal"))) -> Seller Notify
A12: 9 | B12: BB-MKT-00326 | C12: S001 | D12: TechDirect LLC | E12: Smart Home | F12: Amazon | G12: 642520584597 | H12: 0642520584597 | I12: Amazon Hue Starter Kit Smart Home Device | J12: 114.95 | K12: 2024-11-21 | M12: =IF(G12<>"","PASS","FAIL - Missing UPC") -> PASS | N12: =IF(AND(G12<>"",H12<>""),IF("0"&G12=H12,"PASS","FAIL - GTIN Mismatch"),"SKIP") -> PASS | O12: =IF(I12="","FAIL - No Title",IF(LEN(I12)<=126,"PASS","FAIL - Title >"&126&" chars")) -> PASS | P12: =IF(J12>0,IF(J12<5000,"PASS","FLAG - Review Price"),"FAIL - Zero Price") -> PASS | Q12: =IF('Raw Catalog'!P10<>"","PASS","FAIL - No Image") -> PASS | R12: =IF(F12<>"","PASS","FAIL - No Brand") -> PASS | S12: =IF(K12="","FAIL - No Date",IF(TODAY()-DATEVALUE(K12)<=180,"PASS","FLAG - Stale >180d")) -> FLAG - Stale >180d | T12: =COUNTIF(M12:S12,"FAIL*")+COUNTIF(M12:S12,"FLAG*") -> 1 | U12: =IF(T12=0,"CLEAN",IF(T12=1,"MINOR",IF(T12<=3,"MODERATE","CRITICAL"))) -> MINOR | V12: =IF(U12="CLEAN","None",IF(U12="MINOR","Seller Notify",IF(U12="MODERATE","Listing Suspended","Immediate Removal"))) -> Seller Notify
A13: 10 | B13: BB-MKT-00903 | C13: S003 | D13: PrimeElectronics | E13: Headphones | F13: Bose | G13: 274644497411 | H13: 0274644497411 | I13: Bose QuietComfort 45 On-ear Wireless Headphones | J13: 368.82 | K13: 2024-11-15 | M13: =IF(G13<>"","PASS","FAIL - Missing UPC") -> PASS | N13: =IF(AND(G13<>"",H13<>""),IF("0"&G13=H13,"PASS","FAIL - GTIN Mismatch"),"SKIP") -> PASS | O13: =IF(I13="","FAIL - No Title",IF(LEN(I13)<=126,"PASS","FAIL - Title >"&126&" chars")) -> PASS | P13: =IF(J13>0,IF(J13<5000,"PASS","FLAG - Review Price"),"FAIL - Zero Price") -> PASS | Q13: =IF('Raw Catalog'!P11<>"","PASS","FAIL - No Image") -> PASS | R13: =IF(F13<>"","PASS","FAIL - No Brand") -> PASS | S13: =IF(K13="","FAIL - No Date",IF(TODAY()-DATEVALUE(K13)<=180,"PASS","FLAG - Stale >180d")) -> FLAG - Stale >180d | T13: =COUNTIF(M13:S13,"FAIL*")+COUNTIF(M13:S13,"FLAG*") -> 1 | U13: =IF(T13=0,"CLEAN",IF(T13=1,"MINOR",IF(T13<=3,"MODERATE","CRITICAL"))) -> MINOR | V13: =IF(U13="CLEAN","None",IF(U13="MINOR","Seller Notify",IF(U13="MODERATE","Listing Suspended","Immediate Removal"))) -> Seller Notify
A14: 11 | B14: BB-MKT-00900 | C14: S005 | D14: ConnectPro Sales | E14: Headphones | F14: Apple | G14: 717091634913 | H14: 0717091634913 | I14: Apple Studio Pro In-ear Wireless Headphones | J14: 354.48 | K14: 2024-10-02 | M14: =IF(G14<>"","PASS","FAIL - Missing UPC") -> PASS | N14: =IF(AND(G14<>"",H14<>""),IF("0"&G14=H14,"PASS","FAIL - GTIN Mismatch"),"SKIP") -> PASS | O14: =IF(I14="","FAIL - No Title",IF(LEN(I14)<=126,"PASS","FAIL - Title >"&126&" chars")) -> PASS | P14: =IF(J14>0,IF(J14<5000,"PASS","FLAG - Review Price"),"FAIL - Zero Price") -> PASS | Q14: =IF('Raw Catalog'!P12<>"","PASS","FAIL - No Image") -> PASS | R14: =IF(F14<>"","PASS","FAIL - No Brand") -> PASS | S14: =IF(K14="","FAIL - No Date",IF(TODAY()-DATEVALUE(K14)<=180,"PASS","FLAG - Stale >180d")) -> FLAG - Stale >180d | T14: =COUNTIF(M14:S14,"FAIL*")+COUNTIF(M14:S14,"FLAG*") -> 1 | U14: =IF(T14=0,"CLEAN",IF(T14=1,"MINOR",IF(T14<=3,"MODERATE","CRITICAL"))) -> MINOR | V14: =IF(U14="CLEAN","None",IF(U14="MINOR","Seller Notify",IF(U14="MODERATE","Listing Suspended","Immediate Removal"))) -> Seller Notify
A15: 12 | B15: BB-MKT-00826 | C15: S005 | D15: ConnectPro Sales | E15: TVs | F15: Sony | G15: 929014709335 | H15: 0929014709335 | I15: Sony 65" 4K UHD Smart TV Bravia XR | J15: 2129.62 | K15: 2024-09-19 | M15: =IF(G15<>"","PASS","FAIL - Missing UPC") -> PASS | N15: =IF(AND(G15<>"",H15<>""),IF("0"&G15=H15,"PASS","FAIL - GTIN Mismatch"),"SKIP") -> PASS | O15: =IF(I15="","FAIL - No Title",IF(LEN(I15)<=126,"PASS","FAIL - Title >"&126&" chars")) -> PASS | P15: =IF(J15>0,IF(J15<5000,"PASS","FLAG - Review Price"),"FAIL - Zero Price") -> PASS | Q15: =IF('Raw Catalog'!P13<>"","PASS","FAIL - No Image") -> PASS | R15: =IF(F15<>"","PASS","FAIL - No Brand") -> PASS | S15: =IF(K15="","FAIL - No Date",IF(TODAY()-DATEVALUE(K15)<=180,"PASS","FLAG - Stale >180d")) -> FLAG - Stale >180d | T15: =COUNTIF(M15:S15,"FAIL*")+COUNTIF(M15:S15,"FLAG*") -> 1 | U15: =IF(T15=0,"CLEAN",IF(T15=1,"MINOR",IF(T15<=3,"MODERATE","CRITICAL"))) -> MINOR | V15: =IF(U15="CLEAN","None",IF(U15="MINOR","Seller Notify",IF(U15="MODERATE","Listing Suspended","Immediate Removal"))) -> Seller Notify
A16: 13 | B16: BB-MKT-00633 | C16: S006 | D16: NextGen Devices | E16: Laptops | F16: Dell | G16: 235729166419 | H16: 0235729166419 | I16: Dell VivoBook 16 14" Laptop - 64GB RAM 1024GB SSD | J16: 2396.23 | K16: 2025-01-05 | M16: =IF(G16<>"","PASS","FAIL - Missing UPC") -> PASS | N16: =IF(AND(G16<>"",H16<>""),IF("0"&G16=H16,"PASS","FAIL - GTIN Mismatch"),"SKIP") -> PASS | O16: =IF(I16="","FAIL - No Title",IF(LEN(I16)<=126,"PASS","FAIL - Title >"&126&" chars")) -> PASS | P16: =IF(J16>0,IF(J16<5000,"PASS","FLAG - Review Price"),"FAIL - Zero Price") -> PASS | Q16: =IF('Raw Catalog'!P14<>"","PASS","FAIL - No Image") -> PASS | R16: =IF(F16<>"","PASS","FAIL - No Brand") -> PASS | S16: =IF(K16="","FAIL - No Date",IF(TODAY()-DATEVALUE(K16)<=180,"PASS","FLAG - Stale >180d")) -> FLAG - Stale >180d | T16: =COUNTIF(M16:S16,"FAIL*")+COUNTIF(M16:S16,"FLAG*") -> 1 | U16: =IF(T16=0,"CLEAN",IF(T16=1,"MINOR",IF(T16<=3,"MODERATE","CRITICAL"))) -> MINOR | V16: =IF(U16="CLEAN","None",IF(U16="MINOR","Seller Notify",IF(U16="MODERATE","Listing Suspended","Immediate Removal"))) -> Seller Notify
A17: 14 | B17: BB-MKT-00757 | C17: S008 | D17: DigitalHub USA | E17: Headphones | F17: Apple | G17: 670764098449 | H17: 0670764098449 | I17: Apple Tour One Over-ear Wired Headphones | J17: 169.37 | K17: 2024-07-11 | M17: =IF(G17<>"","PASS","FAIL - Missing UPC") -> PASS | N17: =IF(AND(G17<>"",H17<>""),IF("0"&G17=H17,"PASS","FAIL - GTIN Mismatch"),"SKIP") -> PASS | O17: =IF(I17="","FAIL - No Title",IF(LEN(I17)<=126,"PASS","FAIL - Title >"&126&" chars")) -> PASS | P17: =IF(J17>0,IF(J17<5000,"PASS","FLAG - Review Price"),"FAIL - Zero Price") -> PASS | Q17: =IF('Raw Catalog'!P15<>"","PASS","FAIL - No Image") -> PASS | R17: =IF(F17<>"","PASS","FAIL - No Brand") -> PASS | S17: =IF(K17="","FAIL - No Date",IF(TODAY()-DATEVALUE(K17)<=180,"PASS","FLAG - Stale >180d")) -> FLAG - Stale >180d | T17: =COUNTIF(M17:S17,"FAIL*")+COUNTIF(M17:S17,"FLAG*") -> 1 | U17: =IF(T17=0,"CLEAN",IF(T17=1,"MINOR",IF(T17<=3,"MODERATE","CRITICAL"))) -> MINOR | V17: =IF(U17="CLEAN","None",IF(U17="MINOR","Seller Notify",IF(U17="MODERATE","Listing Suspended","Immediate Removal"))) -> Seller Notify
A18: 15 | B18: BB-MKT-00086 | C18: S008 | D18: DigitalHub USA | E18: Tablets | F18: Lenovo | G18: 852274855980 | H18: 0852274855980 | I18: Lenovo iPad Pro 12.9 12.4" 256GB Tablet | J18: 253.91 | K18: 2024-08-19 | M18: =IF(G18<>"","PASS","FAIL - Missing UPC") -> PASS | N18: =IF(AND(G18<>"",H18<>""),IF("0"&G18=H18,"PASS","FAIL - GTIN Mismatch"),"SKIP") -> PASS | O18: =IF(I18="","FAIL - No Title",IF(LEN(I18)<=126,"PASS","FAIL - Title >"&126&" chars")) -> PASS | P18: =IF(J18>0,IF(J18<5000,"PASS","FLAG - Review Price"),"FAIL - Zero Price") -> PASS | Q18: =IF('Raw Catalog'!P16<>"","PASS","FAIL - No Image") -> PASS | R18: =IF(F18<>"","PASS","FAIL - No Brand") -> PASS | S18: =IF(K18="","FAIL - No Date",IF(TODAY()-DATEVALUE(K18)<=180,"PASS","FLAG - Stale >180d")) -> FLAG - Stale >180d | T18: =COUNTIF(M18:S18,"FAIL*")+COUNTIF(M18:S18,"FLAG*") -> 1 | U18: =IF(T18=0,"CLEAN",IF(T18=1,"MINOR",IF(T18<=3,"MODERATE","CRITICAL"))) -> MINOR | V18: =IF(U18="CLEAN","None",IF(U18="MINOR","Seller Notify",IF(U18="MODERATE","Listing Suspended","Immediate Removal"))) -> Seller Notify
A19: 16 | B19: BB-MKT-00189 | C19: S003 | D19: PrimeElectronics | E19: Smart Home | F19: Nest | G19: 633373750765 | H19: 0633373750765 | I19: Nest Learning Thermostat Smart Home Device | J19: 289.81 | K19: 2024-10-04 | M19: =IF(G19<>"","PASS","FAIL - Missing UPC") -> PASS | N19: =IF(AND(G19<>"",H19<>""),IF("0"&G19=H19,"PASS","FAIL - GTIN Mismatch"),"SKIP") -> PASS | O19: =IF(I19="","FAIL - No Title",IF(LEN(I19)<=126,"PASS","FAIL - Title >"&126&" chars")) -> PASS | P19: =IF(J19>0,IF(J19<5000,"PASS","FLAG - Review Price"),"FAIL - Zero Price") -> PASS | Q19: =IF('Raw Catalog'!P17<>"","PASS","FAIL - No Image") -> PASS | R19: =IF(F19<>"","PASS","FAIL - No Brand") -> PASS | S19: =IF(K19="","FAIL - No Date",IF(TODAY()-DATEVALUE(K19)<=180,"PASS","FLAG - Stale >180d")) -> FLAG - Stale >180d | T19: =COUNTIF(M19:S19,"FAIL*")+COUNTIF(M19:S19,"FLAG*") -> 1 | U19: =IF(T19=0,"CLEAN",IF(T19=1,"MINOR",IF(T19<=3,"MODERATE","CRITICAL"))) -> MINOR | V19: =IF(U19="CLEAN","None",IF(U19="MINOR","Seller Notify",IF(U19="MODERATE","Listing Suspended","Immediate Removal"))) -> Seller Notify
A20: 17 | B20: BB-MKT-00407 | C20: S003 | D20: PrimeElectronics | E20: Tablets | F20: Lenovo | G20: 965724580023 | H20: 0466172926771 | I20: Lenovo iPad Pro 12.9 10.1" 256GB Tablet | J20: 348.05 | K20: 2025-04-20 | L20: GTIN_UPC_MISMATCH | M20: =IF(G20<>"","PASS","FAIL - Missing UPC") -> PASS | N20: =IF(AND(G20<>"",H20<>""),IF("0"&G20=H20,"PASS","FAIL - GTIN Mismatch"),"SKIP") -> FAIL - GTIN Mismatch | O20: =IF(I20="","FAIL - No Title",IF(LEN(I20)<=126,"PASS","FAIL - Title >"&126&" chars")) -> PASS | P20: =IF(J20>0,IF(J20<5000,"PASS","FLAG - Review Price"),"FAIL - Zero Price") -> PASS | Q20: =IF('Raw Catalog'!P18<>"","PASS","FAIL - No Image") -> PASS | R20: =IF(F20<>"","PASS","FAIL - No Brand") -> PASS | S20: =IF(K20="","FAIL - No Date",IF(TODAY()-DATEVALUE(K20)<=180,"PASS","FLAG - Stale >180d")) -> FLAG - Stale >180d | T20: =COUNTIF(M20:S20,"FAIL*")+COUNTIF(M20:S20,"FLAG*") -> 2 | U20: =IF(T20=0,"CLEAN",IF(T20=1,"MINOR",IF(T20<=3,"MODERATE","CRITICAL"))) -> MODERATE | V20: =IF(U20="CLEAN","None",IF(U20="MINOR","Seller Notify",IF(U20="MODERATE","Listing Suspended","Immediate Removal"))) -> Listing Suspended
A21: 18 | B21: BB-MKT-00004 | C21: S002 | D21: EliteGadgets Inc | E21: Smart Home | F21: Ring | G21: 147543377362 | H21: 0147543377362 | I21: Ring Hue Starter Kit Smart Home Device | J21: 492.05 | K21: 2024-08-21 | M21: =IF(G21<>"","PASS","FAIL - Missing UPC") -> PASS | N21: =IF(AND(G21<>"",H21<>""),IF("0"&G21=H21,"PASS","FAIL - GTIN Mismatch"),"SKIP") -> PASS | O21: =IF(I21="","FAIL - No Title",IF(LEN(I21)<=126,"PASS","FAIL - Title >"&126&" chars")) -> PASS | P21: =IF(J21>0,IF(J21<5000,"PASS","FLAG - Review Price"),"FAIL - Zero Price") -> PASS | Q21: =IF('Raw Catalog'!P19<>"","PASS","FAIL - No Image") -> PASS | R21: =IF(F21<>"","PASS","FAIL - No Brand") -> PASS | S21: =IF(K21="","FAIL - No Date",IF(TODAY()-DATEVALUE(K21)<=180,"PASS","FLAG - Stale >180d")) -> FLAG - Stale >180d | T21: =COUNTIF(M21:S21,"FAIL*")+COUNTIF(M21:S21,"FLAG*") -> 1 | U21: =IF(T21=0,"CLEAN",IF(T21=1,"MINOR",IF(T21<=3,"MODERATE","CRITICAL"))) -> MINOR | V21: =IF(U21="CLEAN","None",IF(U21="MINOR","Seller Notify",IF(U21="MODERATE","Listing Suspended","Immediate Removal"))) -> Seller Notify
A22: 19 | B22: BB-MKT-00729 | C22: S004 | D22: ValueTech Store | E22: Headphones | F22: Bose | G22: 158666065098 | H22: 0158666065098 | I22: Bose Momentum 4 Over-ear Both Headphones | J22: 515.19 | K22: 2025-04-23 | M22: =IF(G22<>"","PASS","FAIL - Missing UPC") -> PASS | N22: =IF(AND(G22<>"",H22<>""),IF("0"&G22=H22,"PASS","FAIL - GTIN Mismatch"),"SKIP") -> PASS | O22: =IF(I22="","FAIL - No Title",IF(LEN(I22)<=126,"PASS","FAIL - Title >"&126&" chars")) -> PASS | P22: =IF(J22>0,IF(J22<5000,"PASS","FLAG - Review Price"),"FAIL - Zero Price") -> PASS | Q22: =IF('Raw Catalog'!P20<>"","PASS","FAIL - No Image") -> PASS | R22: =IF(F22<>"","PASS","FAIL - No Brand") -> PASS | S22: =IF(K22="","FAIL - No Date",IF(TODAY()-DATEVALUE(K22)<=180,"PASS","FLAG - Stale >180d")) -> FLAG - Stale >180d | T22: =COUNTIF(M22:S22,"FAIL*")+COUNTIF(M22:S22,"FLAG*") -> 1 | U22: =IF(T22=0,"CLEAN",IF(T22=1,"MINOR",IF(T22<=3,"MODERATE","CRITICAL"))) -> MINOR | V22: =IF(U22="CLEAN","None",IF(U22="MINOR","Seller Notify",IF(U22="MODERATE","Listing Suspended","Immediate Removal"))) -> Seller Notify
A23: 20 | B23: BB-MKT-00319 | C23: S008 | D23: DigitalHub USA | E23: Tablets | F23: Apple | H23: 0669128469380 | I23: Apple Galaxy Tab S9 10.1" 256GB Tablet | J23: 924.13 | K23: 2024-07-01 | L23: MISSING_UPC | M23: =IF(G23<>"","PASS","FAIL - Missing UPC") -> FAIL - Missing UPC | N23: =IF(AND(G23<>"",H23<>""),IF("0"&G23=H23,"PASS","FAIL - GTIN Mismatch"),"SKIP") -> SKIP | O23: =IF(I23="","FAIL - No Title",IF(LEN(I23)<=126,"PASS","FAIL - Title >"&126&" chars")) -> PASS | P23: =IF(J23>0,IF(J23<5000,"PASS","FLAG - Review Price"),"FAIL - Zero Price") -> PASS | Q23: =IF('Raw Catalog'!P21<>"","PASS","FAIL - No Image") -> PASS | R23: =IF(F23<>"","PASS","FAIL - No Brand") -> PASS | S23: =IF(K23="","FAIL - No Date",IF(TODAY()-DATEVALUE(K23)<=180,"PASS","FLAG - Stale >180d")) -> FLAG - Stale >180d | T23: =COUNTIF(M23:S23,"FAIL*")+COUNTIF(M23:S23,"FLAG*") -> 2 | U23: =IF(T23=0,"CLEAN",IF(T23=1,"MINOR",IF(T23<=3,"MODERATE","CRITICAL"))) -> MODERATE | V23: =IF(U23="CLEAN","None",IF(U23="MINOR","Seller Notify",IF(U23="MODERATE","Listing Suspended","Immediate Removal"))) -> Listing Suspended
A24: 21 | B24: BB-MKT-00247 | C24: S002 | D24: EliteGadgets Inc | E24: Smart Home | F24: Nest | G24: 370830447947 | H24: 0370830447947 | I24: Nest Nest Hub Max Smart Home Device | J24: 48.28 | K24: 2024-11-18 | L24: DUPLICATE_SKU | M24: =IF(G24<>"","PASS","FAIL - Missing UPC") -> PASS | N24: =IF(AND(G24<>"",H24<>""),IF("0"&G24=H24,"PASS","FAIL - GTIN Mismatch"),"SKIP") -> PASS | O24: =IF(I24="","FAIL - No Title",IF(LEN(I24)<=126,"PASS","FAIL - Title >"&126&" chars")) -> PASS | P24: =IF(J24>0,IF(J24<5000,"PASS","FLAG - Review Price"),"FAIL - Zero Price") -> PASS | Q24: =IF('Raw Catalog'!P22<>"","PASS","FAIL - No Image") -> PASS | R24: =IF(F24<>"","PASS","FAIL - No Brand") -> PASS | S24: =IF(K24="","FAIL - No Date",IF(TODAY()-DATEVALUE(K24)<=180,"PASS","FLAG - Stale >180d")) -> FLAG - Stale >180d | T24: =COUNTIF(M24:S24,"FAIL*")+COUNTIF(M24:S24,"FLAG*") -> 1 | U24: =IF(T24=0,"CLEAN",IF(T24=1,"MINOR",IF(T24<=3,"MODERATE","CRITICAL"))) -> MINOR | V24: =IF(U24="CLEAN","None",IF(U24="MINOR","Seller Notify",IF(U24="MODERATE","Listing Suspended","Immediate Removal"))) -> Seller Notify
A25: 22 | B25: BB-MKT-00230 | C25: S002 | D25: EliteGadgets Inc | E25: Headphones | F25: Apple | G25: 450680559005 | H25: 0450680559005 | I25: Apple AirPods Max Over-ear Wireless Headphones | J25: 145.08 | K25: 2025-01-10 | M25: =IF(G25<>"","PASS","FAIL - Missing UPC") -> PASS | N25: =IF(AND(G25<>"",H25<>""),IF("0"&G25=H25,"PASS","FAIL - GTIN Mismatch"),"SKIP") -> PASS | O25: =IF(I25="","FAIL - No Title",IF(LEN(I25)<=126,"PASS","FAIL - Title >"&126&" chars")) -> PASS | P25: =IF(J25>0,IF(J25<5000,"PASS","FLAG - Review Price"),"FAIL - Zero Price") -> PASS | Q25: =IF('Raw Catalog'!P23<>"","PASS","FAIL - No Image") -> PASS | R25: =IF(F25<>"","PASS","FAIL - No Brand") -> PASS | S25: =IF(K25="","FAIL - No Date",IF(TODAY()-DATEVALUE(K25)<=180,"PASS","FLAG - Stale >180d")) -> FLAG - Stale >180d | T25: =COUNTIF(M25:S25,"FAIL*")+COUNTIF(M25:S25,"FLAG*") -> 1 | U25: =IF(T25=0,"CLEAN",IF(T25=1,"MINOR",IF(T25<=3,"MODERATE","CRITICAL"))) -> MINOR | V25: =IF(U25="CLEAN","None",IF(U25="MINOR","Seller Notify",IF(U25="MODERATE","Listing Suspended","Immediate Removal"))) -> Seller Notify
A26: 23 | B26: BB-MKT-00185 | C26: S001 | D26: TechDirect LLC | E26: Headphones | F26: Jabra | G26: 706339659651 | H26: 0706339659651 | I26: Jabra WH-1000XM5 In-ear Wireless Headphones | J26: 320.12 | K26: 2025-01-24 | M26: =IF(G26<>"","PASS","FAIL - Missing UPC") -> PASS | N26: =IF(AND(G26<>"",H26<>""),IF("0"&G26=H26,"PASS","FAIL - GTIN Mismatch"),"SKIP") -> PASS | O26: =IF(I26="","FAIL - No Title",IF(LEN(I26)<=126,"PASS","FAIL - Title >"&126&" chars")) -> PASS | P26: =IF(J26>0,IF(J26<5000,"PASS","FLAG - Review Price"),"FAIL - Zero Price") -> PASS | Q26: =IF('Raw Catalog'!P24<>"","PASS","FAIL - No Image") -> PASS | R26: =IF(F26<>"","PASS","FAIL - No Brand") -> PASS | S26: =IF(K26="","FAIL - No Date",IF(TODAY()-DATEVALUE(K26)<=180,"PASS","FLAG - Stale >180d")) -> FLAG - Stale >180d | T26: =COUNTIF(M26:S26,"FAIL*")+COUNTIF(M26:S26,"FLAG*") -> 1 | U26: =IF(T26=0,"CLEAN",IF(T26=1,"MINOR",IF(T26<=3,"MODERATE","CRITICAL"))) -> MINOR | V26: =IF(U26="CLEAN","None",IF(U26="MINOR","Seller Notify",IF(U26="MODERATE","Listing Suspended","Immediate Removal"))) -> Seller Notify
A27: 24 | B27: BB-MKT-00359 | C27: S001 | D27: TechDirect LLC | E27: Headphones | F27: Sennheiser | G27: 332881230114 | H27: 0332881230114 | I27: Sennheiser WH-1000XM5 In-ear Wireless Headphones | J27: 430.19 | K27: 2024-11-19 | M27: =IF(G27<>"","PASS","FAIL - Missing UPC") -> PASS | N27: =IF(AND(G27<>"",H27<>""),IF("0"&G27=H27,"PASS","FAIL - GTIN Mismatch"),"SKIP") -> PASS | O27: =IF(I27="","FAIL - No Title",IF(LEN(I27)<=126,"PASS","FAIL - Title >"&126&" chars")) -> PASS | P27: =IF(J27>0,IF(J27<5000,"PASS","FLAG - Review Price"),"FAIL - Zero Price") -> PASS | Q27: =IF('Raw Catalog'!P25<>"","PASS","FAIL - No Image") -> PASS | R27: =IF(F27<>"","PASS","FAIL - No Brand") -> PASS | S27: =IF(K27="","FAIL - No Date",IF(TODAY()-DATEVALUE(K27)<=180,"PASS","FLAG - Stale >180d")) -> FLAG - Stale >180d | T27: =COUNTIF(M27:S27,"FAIL*")+COUNTIF(M27:S27,"FLAG*") -> 1 | U27: =IF(T27=0,"CLEAN",IF(T27=1,"MINOR",IF(T27<=3,"MODERATE","CRITICAL"))) -> MINOR | V27: =IF(U27="CLEAN","None",IF(U27="MINOR","Seller Notify",IF(U27="MODERATE","Listing Suspended","Immediate Removal"))) -> Seller Notify
A28: 25 | B28: BB-MKT-00513 | C28: S001 | D28: TechDirect LLC | E28: Headphones | F28: Sennheiser | G28: 718012404580 | H28: 0718012404580 | I28: Sennheiser Momentum 4 On-ear Wired Headphones | J28: 164.35 | K28: 2023-11-30 | L28: STALE_LISTING | M28: =IF(G28<>"","PASS","FAIL - Missing UPC") -> PASS | N28: =IF(AND(G28<>"",H28<>""),IF("0"&G28=H28,"PASS","FAIL - GTIN Mismatch"),"SKIP") -> PASS | O28: =IF(I28="","FAIL - No Title",IF(LEN(I28)<=126,"PASS","FAIL - Title >"&126&" chars")) -> PASS | P28: =IF(J28>0,IF(J28<5000,"PASS","FLAG - Review Price"),"FAIL - Zero Price") -> PASS | Q28: =IF('Raw Catalog'!P26<>"","PASS","FAIL - No Image") -> PASS | R28: =IF(F28<>"","PASS","FAIL - No Brand") -> PASS | S28: =IF(K28="","FAIL - No Date",IF(TODAY()-DATEVALUE(K28)<=180,"PASS","FLAG - Stale >180d")) -> FLAG - Stale >180d | T28: =COUNTIF(M28:S28,"FAIL*")+COUNTIF(M28:S28,"FLAG*") -> 1 | U28: =IF(T28=0,"CLEAN",IF(T28=1,"MINOR",IF(T28<=3,"MODERATE","CRITICAL"))) -> MINOR | V28: =IF(U28="CLEAN","None",IF(U28="MINOR","Seller Notify",IF(U28="MODERATE","Listing Suspended","Immediate Removal"))) -> Seller Notify
A29: 26 | B29: BB-MKT-00453 | C29: S004 | D29: ValueTech Store | E29: TVs | F29: Sony | G29: 168953380650 | H29: 0168953380650 | I29: Sony 55" 1080p Full HD Smart TV Bravia XR | J29: 1945.54 | K29: 2024-09-01 | M29: =IF(G29<>"","PASS","FAIL - Missing UPC") -> PASS | N29: =IF(AND(G29<>"",H29<>""),IF("0"&G29=H29,"PASS","FAIL - GTIN Mismatch"),"SKIP") -> PASS | O29: =IF(I29="","FAIL - No Title",IF(LEN(I29)<=126,"PASS","FAIL - Title >"&126&" chars")) -> PASS | P29: =IF(J29>0,IF(J29<5000,"PASS","FLAG - Review Price"),"FAIL - Zero Price") -> PASS | Q29: =IF('Raw Catalog'!P27<>"","PASS","FAIL - No Image") -> PASS | R29: =IF(F29<>"","PASS","FAIL - No Brand") -> PASS | S29: =IF(K29="","FAIL - No Date",IF(TODAY()-DATEVALUE(K29)<=180,"PASS","FLAG - Stale >180d")) -> FLAG - Stale >180d | T29: =COUNTIF(M29:S29,"FAIL*")+COUNTIF(M29:S29,"FLAG*") -> 1 | U29: =IF(T29=0,"CLEAN",IF(T29=1,"MINOR",IF(T29<=3,"MODERATE","CRITICAL"))) -> MINOR | V29: =IF(U29="CLEAN","None",IF(U29="MINOR","Seller Notify",IF(U29="MODERATE","Listing Suspended","Immediate Removal"))) -> Seller Notify
A30: 27 | B30: BB-MKT-00845 | C30: S007 | D30: SmartBuy Co | E30: Headphones | F30: Bose | G30: 312712561451 | H30: 0312712561451 | I30: Bose Evolve2 85 Over-ear Wireless Headphones | J30: 3839.84 | K30: 2024-11-07 | L30: PRICE_ANOMALY | M30: =IF(G30<>"","PASS","FAIL - Missing UPC") -> PASS | N30: =IF(AND(G30<>"",H30<>""),IF("0"&G30=H30,"PASS","FAIL - GTIN Mismatch"),"SKIP") -> PASS | O30: =IF(I30="","FAIL - No Title",IF(LEN(I30)<=126,"PASS","FAIL - Title >"&126&" chars")) -> PASS | P30: =IF(J30>0,IF(J30<5000,"PASS","FLAG - Review Price"),"FAIL - Zero Price") -> PASS | Q30: =IF('Raw Catalog'!P28<>"","PASS","FAIL - No Image") -> PASS | R30: =IF(F30<>"","PASS","FAIL - No Brand") -> PASS | S30: =IF(K30="","FAIL - No Date",IF(TODAY()-DATEVALUE(K30)<=180,"PASS","FLAG - Stale >180d")) -> FLAG - Stale >180d | T30: =COUNTIF(M30:S30,"FAIL*")+COUNTIF(M30:S30,"FLAG*") -> 1 | U30: =IF(T30=0,"CLEAN",IF(T30=1,"MINOR",IF(T30<=3,"MODERATE","CRITICAL"))) -> MINOR | V30: =IF(U30="CLEAN","None",IF(U30="MINOR","Seller Notify",IF(U30="MODERATE","Listing Suspended","Immediate Removal"))) -> Seller Notify
A31: 28 | B31: BB-MKT-00932 | C31: S003 | D31: PrimeElectronics | E31: Headphones | F31: Apple | G31: 534576011084 | H31: 0534576011084 | I31: Apple Tour One On-ear Both Headphones | J31: 102.69 | K31: 2024-07-09 | M31: =IF(G31<>"","PASS","FAIL - Missing UPC") -> PASS | N31: =IF(AND(G31<>"",H31<>""),IF("0"&G31=H31,"PASS","FAIL - GTIN Mismatch"),"SKIP") -> PASS | O31: =IF(I31="","FAIL - No Title",IF(LEN(I31)<=126,"PASS","FAIL - Title >"&126&" chars")) -> PASS | P31: =IF(J31>0,IF(J31<5000,"PASS","FLAG - Review Price"),"FAIL - Zero Price") -> PASS | Q31: =IF('Raw Catalog'!P29<>"","PASS","FAIL - No Image") -> PASS | R31: =IF(F31<>"","PASS","FAIL - No Brand") -> PASS | S31: =IF(K31="","FAIL - No Date",IF(TODAY()-DATEVALUE(K31)<=180,"PASS","FLAG - Stale >180d")) -> FLAG - Stale >180d | T31: =COUNTIF(M31:S31,"FAIL*")+COUNTIF(M31:S31,"FLAG*") -> 1 | U31: =IF(T31=0,"CLEAN",IF(T31=1,"MINOR",IF(T31<=3,"MODERATE","CRITICAL"))) -> MINOR | V31: =IF(U31="CLEAN","None",IF(U31="MINOR","Seller Notify",IF(U31="MODERATE","Listing Suspended","Immediate Removal"))) -> Seller Notify
A32: 29 | B32: BB-MKT-00799 | C32: S004 | D32: ValueTech Store | E32: Tablets | F32: Apple | G32: 299460168950 | H32: 0299460168950 | I32: Apple Fire HD 10 11" 64GB Tablet | J32: 447.47 | K32: 2024-09-28 | M32: =IF(G32<>"","PASS","FAIL - Missing UPC") -> PASS | N32: =IF(AND(G32<>"",H32<>""),IF("0"&G32=H32,"PASS","FAIL - GTIN Mismatch"),"SKIP") -> PASS | O32: =IF(I32="","FAIL - No Title",IF(LEN(I32)<=126,"PASS","FAIL - Title >"&126&" chars")) -> PASS | P32: =IF(J32>0,IF(J32<5000,"PASS","FLAG - Review Price"),"FAIL - Zero Price") -> PASS | Q32: =IF('Raw Catalog'!P30<>"","PASS","FAIL - No Image") -> PASS | R32: =IF(F32<>"","PASS","FAIL - No Brand") -> PASS | S32: =IF(K32="","FAIL - No Date",IF(TODAY()-DATEVALUE(K32)<=180,"PASS","FLAG - Stale >180d")) -> FLAG - Stale >180d | T32: =COUNTIF(M32:S32,"FAIL*")+COUNTIF(M32:S32,"FLAG*") -> 1 | U32: =IF(T32=0,"CLEAN",IF(T32=1,"MINOR",IF(T32<=3,"MODERATE","CRITICAL"))) -> MINOR | V32: =IF(U32="CLEAN","None",IF(U32="MINOR","Seller Notify",IF(U32="MODERATE","Listing Suspended","Immediate Removal"))) -> Seller Notify
A33: 30 | B33: BB-MKT-00448 | C33: S001 | D33: TechDirect LLC | E33: Tablets | F33: Amazon | G33: 979651034336 | H33: 0979651034336 | I33: Amazon iPad Pro 12.9 12.9" 512GB Tablet | J33: 718.58 | K33: 2024-07-07 | M33: =IF(G33<>"","PASS","FAIL - Missing UPC") -> PASS | N33: =IF(AND(G33<>"",H33<>""),IF("0"&G33=H33,"PASS","FAIL - GTIN Mismatch"),"SKIP") -> PASS | O33: =IF(I33="","FAIL - No Title",IF(LEN(I33)<=126,"PASS","FAIL - Title >"&126&" chars")) -> PASS | P33: =IF(J33>0,IF(J33<5000,"PASS","FLAG - Review Price"),"FAIL - Zero Price") -> PASS | Q33: =IF('Raw Catalog'!P31<>"","PASS","FAIL - No Image") -> PASS | R33: =IF(F33<>"","PASS","FAIL - No Brand") -> PASS | S33: =IF(K33="","FAIL - No Date",IF(TODAY()-DATEVALUE(K33)<=180,"PASS","FLAG - Stale >180d")) -> FLAG - Stale >180d | T33: =COUNTIF(M33:S33,"FAIL*")+COUNTIF(M33:S33,"FLAG*") -> 1 | U33: =IF(T33=0,"CLEAN",IF(T33=1,"MINOR",IF(T33<=3,"MODERATE","CRITICAL"))) -> MINOR | V33: =IF(U33="CLEAN","None",IF(U33="MINOR","Seller Notify",IF(U33="MODERATE","Listing Suspended","Immediate Removal"))) -> Seller Notify
A34: 31 | B34: BB-MKT-00721 | C34: S007 | D34: SmartBuy Co | E34: Smart Home | F34: Philips | G34: 509861786750 | H34: 0509861786750 | I34: Philips Video Doorbell Pro 2 Smart Home Device | J34: 284.1 | K34: 2025-02-09 | M34: =IF(G34<>"","PASS","FAIL - Missing UPC") -> PASS | N34: =IF(AND(G34<>"",H34<>""),IF("0"&G34=H34,"PASS","FAIL - GTIN Mismatch"),"SKIP") -> PASS | O34: =IF(I34="","FAIL - No Title",IF(LEN(I34)<=126,"PASS","FAIL - Title >"&126&" chars")) -> PASS | P34: =IF(J34>0,IF(J34<5000,"PASS","FLAG - Review Price"),"FAIL - Zero Price") -> PASS | Q34: =IF('Raw Catalog'!P32<>"","PASS","FAIL - No Image") -> PASS | R34: =IF(F34<>"","PASS","FAIL - No Brand") -> PASS | S34: =IF(K34="","FAIL - No Date",IF(TODAY()-DATEVALUE(K34)<=180,"PASS","FLAG - Stale >180d")) -> FLAG - Stale >180d | T34: =COUNTIF(M34:S34,"FAIL*")+COUNTIF(M34:S34,"FLAG*") -> 1 | U34: =IF(T34=0,"CLEAN",IF(T34=1,"MINOR",IF(T34<=3,"MODERATE","CRITICAL"))) -> MINOR | V34: =IF(U34="CLEAN","None",IF(U34="MINOR","Seller Notify",IF(U34="MODERATE","Listing Suspended","Immediate Removal"))) -> Seller Notify
A35: 32 | B35: BB-MKT-00306 | C35: S005 | D35: ConnectPro Sales | E35: Tablets | F35: Samsung | G35: 631685415257 | H35: 0631685415257 | I35: Samsung Fire HD 10 11" 512GB Tablet | J35: 654.88 | K35: 2024-11-21 | M35: =IF(G35<>"","PASS","FAIL - Missing UPC") -> PASS | N35: =IF(AND(G35<>"",H35<>""),IF("0"&G35=H35,"PASS","FAIL - GTIN Mismatch"),"SKIP") -> PASS | O35: =IF(I35="","FAIL - No Title",IF(LEN(I35)<=126,"PASS","FAIL - Title >"&126&" chars")) -> PASS | P35: =IF(J35>0,IF(J35<5000,"PASS","FLAG - Review Price"),"FAIL - Zero Price") -> PASS | Q35: =IF('Raw Catalog'!P33<>"","PASS","FAIL - No Image") -> PASS | R35: =IF(F35<>"","PASS","FAIL - No Brand") -> PASS | S35: =IF(K35="","FAIL - No Date",IF(TODAY()-DATEVALUE(K35)<=180,"PASS","FLAG - Stale >180d")) -> FLAG - Stale >180d | T35: =COUNTIF(M35:S35,"FAIL*")+COUNTIF(M35:S35,"FLAG*") -> 1 | U35: =IF(T35=0,"CLEAN",IF(T35=1,"MINOR",IF(T35<=3,"MODERATE","CRITICAL"))) -> MINOR | V35: =IF(U35="CLEAN","None",IF(U35="MINOR","Seller Notify",IF(U35="MODERATE","Listing Suspended","Immediate Removal"))) -> Seller Notify
